Workbook

Sheet Versie beheer
A2: datum | B2: wijziging | C2: Versie
A3: 1e helft 2025 | B3: alle variabele invoer cellen op nul gezet, gFF zekeringen toegevoegd, werkblad met OVL lengtes toegevoegd | C3: 1.0
A4: 45839 | B4: de nieuwe tabellen voor toekomstige aansluitwaarden kleinzakelijk en grootzakelijk toegevoegd op werkbladen ontwerpstroom_trafo en _kabel | C4: 2.0
A5: 45931 | B5: Per afgaande LS-kabel is er één werkblad gemaakt. De kabel lengteberekeningen zijn ook per werkblad geplaatst, zodat we één tabblad hebben per richting . De kleuren van de tabbladen komen overeen met de lijn kleuren in de SO-tekenhulp. De huidige E-aansluitwaarde wordt tezamen met de eventueel aanwezige gasaansluiting tot een E-equivalent berekend. De aantallen per kabelrichting worden automatisch gesommeerd op het trafowerkblad, waarbij de op dat netvlak van toepassing zijnde belasting- en opwekwaardes zijn verwerkt. Tevens is het OVL lengte werkblad geüpdatet. Bijstellen van de PV adoptie o.b.v. het nieuwe EV26 scenario. Correctie van de vermogens van netbewust laden. Hierbij wordt nu het vermogen tijdens de netbewust laden periode gebruikt. Onderscheid gemaakt tussen bestaande en nieuwbouw huishoudens. Behalve uiteraard de gele invoercellen zijn de werkbladen zonder wachtwoord beveiligd. | C5: 3.0
A6: 46023 | B6: Correctie van de ontwerpstromen en -vermogens van type 1 t/m type 6 door aanpassen van het uitgangspunt voor etmaal temperatuur tijdens de verbruikspiek. Opwekwaardes eigenrichting 3x100A en 3x125A verlaagd tot dezelfde waardes als belasting in case G4, G6, geen of ander gas. Onderscheiden van ontwerpstromen o.b.v. bouwjaar. | C6: 3.1

Sheet Transformator
B1: Ontwerpstroom transformator (let op: kolom A is automatische optelsom van alle afgaande kabelrichtingen)
B2: Aantal van eenheid | C2: Type wooneenheid | F2: Ontwerpstroom verbruik per eenheid | G2: Ontwerpstroom opwek per eenheid | H2: Totaal verbruik op trafoniveau in A | I2: Totaal opwek op trafoniveau in A | J2: Totaal verbruik op trafoniveau in kW | K2: Totaal opwek op trafoniveau in kW
C4: Type 1: Laagbouw huishoudens t/m bouwjaar 2021 met een individuele warmtepomp en tapwaterbuffer
B5: ='(1)'!B5+'(2)'!B5+'(3)'!B5+'(4)'!B5+'(5)'!B5+'(6)'!B5+'(7)'!B5+'(8)'!B5+'(9)'!B5+'(10)'!B5+'(11)'!B5+'(12)'!B5 | C5: Vrijstaand | F5: 7.5 | G5: 8.9 | H5: =F5*B5 | I5: =G5*B5 | J5: =F5*0.23*3*B5 | K5: =G5*0.23*3*B5
B6: ='(1)'!B6+'(2)'!B6+'(3)'!B6+'(4)'!B6+'(5)'!B6+'(6)'!B6+'(7)'!B6+'(8)'!B6+'(9)'!B6+'(10)'!B6+'(11)'!B6+'(12)'!B6 | C6: Twee onder een kap | F6: 6.3 | G6: 6.8 | H6: =F6*B6 | I6: =G6*B6 | J6: =F6*0.23*3*B6 | K6: =G6*0.23*3*B6
B7: ='(1)'!B7+'(2)'!B7+'(3)'!B7+'(4)'!B7+'(5)'!B7+'(6)'!B7+'(7)'!B7+'(8)'!B7+'(9)'!B7+'(10)'!B7+'(11)'!B7+'(12)'!B7 | C7: Rijtjeswoning (woonboten, woonwagens, chalets en vakantiehuisjes) | F7: 5.5 | G7: 5.7 | H7: =F7*B7 | I7: =G7*B7 | J7: =F7*0.23*3*B7 | K7: =G7*0.23*3*B7
B8: ='(1)'!B8+'(2)'!B8+'(3)'!B8+'(4)'!B8+'(5)'!B8+'(6)'!B8+'(7)'!B8+'(8)'!B8+'(9)'!B8+'(10)'!B8+'(11)'!B8+'(12)'!B8 | C8: Onbekend | F8: 5.9 | G8: 5.7 | H8: =F8*B8 | I8: =G8*B8 | J8: =F8*0.23*3*B8 | K8: =G8*0.23*3*B8
C10: Type 2: Laagbouw huishoudens met stads- of gasverwarming
B11: ='(1)'!B11+'(2)'!B11+'(3)'!B11+'(4)'!B11+'(5)'!B11+'(6)'!B11+'(7)'!B11+'(8)'!B11+'(9)'!B11+'(10)'!B11+'(11)'!B11+'(12)'!B11 | C11: Vrijstaand | F11: 3.9 | G11: 8.9 | H11: =F11*B11 | I11: =G11*B11 | J11: =F11*0.23*3*B11 | K11: =G11*0.23*3*B11
B12: ='(1)'!B12+'(2)'!B12+'(3)'!B12+'(4)'!B12+'(5)'!B12+'(6)'!B12+'(7)'!B12+'(8)'!B12+'(9)'!B12+'(10)'!B12+'(11)'!B12+'(12)'!B12 | C12: Twee onder een kap | F12: 3.9 | G12: 6.8 | H12: =F12*B12 | I12: =G12*B12 | J12: =F12*0.23*3*B12 | K12: =G12*0.23*3*B12
B13: ='(1)'!B13+'(2)'!B13+'(3)'!B13+'(4)'!B13+'(5)'!B13+'(6)'!B13+'(7)'!B13+'(8)'!B13+'(9)'!B13+'(10)'!B13+'(11)'!B13+'(12)'!B13 | C13: Rijtjeswoning (woonboten, woonwagens, chalets en vakantiehuisjes) | F13: 3.9 | G13: 5.7 | H13: =F13*B13 | I13: =G13*B13 | J13: =F13*0.23*3*B13 | K13: =G13*0.23*3*B13
B14: ='(1)'!B14+'(2)'!B14+'(3)'!B14+'(4)'!B14+'(5)'!B14+'(6)'!B14+'(7)'!B14+'(8)'!B14+'(9)'!B14+'(10)'!B14+'(11)'!B14+'(12)'!B14 | C14: Onbekend | F14: 3.9 | G14: 5.7 | H14: =F14*B14 | I14: =G14*B14 | J14: =F14*0.23*3*B14 | K14: =G14*0.23*3*B14
C16: Type 3: Laagbouw huishoudens vanaf bouwjaar 2022 met een individuele warmtepomp en tapwaterbuffer
B17: ='(1)'!B17+'(2)'!B17+'(3)'!B17+'(4)'!B17+'(5)'!B17+'(6)'!B17+'(7)'!B17+'(8)'!B17+'(9)'!B17+'(10)'!B17+'(11)'!B17+'(12)'!B17 | C17: Vrijstaand | F17: 7 | G17: 8.9 | H17: =F17*B17 | I17: =G17*B17 | J17: =F17*0.23*3*B17 | K17: =G17*0.23*3*B17
B18: ='(1)'!B18+'(2)'!B18+'(3)'!B18+'(4)'!B18+'(5)'!B18+'(6)'!B18+'(7)'!B18+'(8)'!B18+'(9)'!B18+'(10)'!B18+'(11)'!B18+'(12)'!B18 | C18: Twee onder een kap | F18: 5.9 | G18: 6.8 | H18: =F18*B18 | I18: =G18*B18 | J18: =F18*0.23*3*B18 | K18: =G18*0.23*3*B18
B19: ='(1)'!B19+'(2)'!B19+'(3)'!B19+'(4)'!B19+'(5)'!B19+'(6)'!B19+'(7)'!B19+'(8)'!B19+'(9)'!B19+'(10)'!B19+'(11)'!B19+'(12)'!B19 | C19: Rijtjeswoning | F19: 5.3 | G19: 5.7 | H19: =F19*B19 | I19: =G19*B19 | J19: =F19*0.23*3*B19 | K19: =G19*0.23*3*B19
B20: ='(1)'!B20+'(2)'!B20+'(3)'!B20+'(4)'!B20+'(5)'!B20+'(6)'!B20+'(7)'!B20+'(8)'!B20+'(9)'!B20+'(10)'!B20+'(11)'!B20+'(12)'!B20 | C20: Onbekend | F20: 5.6 | G20: 5.7 | H20: =F20*B20 | I20: =G20*B20 | J20: =F20*0.23*3*B20 | K20: =G20*0.23*3*B20
C22: Type 4: Hoogbouw huishoudens met collectieve warmtepomp, stads- of gasverwarming
B23: ='(1)'!B23+'(2)'!B23+'(3)'!B23+'(4)'!B23+'(5)'!B23+'(6)'!B23+'(7)'!B23+'(8)'!B23+'(9)'!B23+'(10)'!B23+'(11)'!B23+'(12)'!B23 | C23: Appartement incl. publiek laden | F23: 2.6 | H23: =F23*B23 | J23: =F23*0.23*3*B23
C24: Collectieve warmtepomp - elektrisch vermogen | H24: =J24*1000/(3*230) | J24: ='(1)'!J24+'(2)'!J24+'(3)'!J24+'(4)'!J24+'(5)'!J24+'(6)'!J24+'(7)'!J24+'(8)'!J24+'(9)'!J24+'(10)'!J24+'(11)'!J24+'(12)'!J24
N25: Toekomstige aansluitwaarden kleinzakelijk en grootverbruik:
C26: Type 5: Hoogbouw huishoudens t/m bouwjaar 2021 met een individuele warmtepomp
B27: ='(1)'!B27+'(2)'!B27+'(3)'!B27+'(4)'!B27+'(5)'!B27+'(6)'!B27+'(7)'!B27+'(8)'!B27+'(9)'!B27+'(10)'!B27+'(11)'!B27+'(12)'!B27 | C27: Appartement incl. publiek laden | F27: 4.5 | H27: =F27*B27 | J27: =F27*0.23*3*B27
C29: Type 6: Nieuwbouw hoogbouw huishoudens vanaf bouwjaar 2022 met een individuele warmtepomp
B30: ='(1)'!B30+'(2)'!B30+'(3)'!B30+'(4)'!B30+'(5)'!B30+'(6)'!B30+'(7)'!B30+'(8)'!B30+'(9)'!B30+'(10)'!B30+'(11)'!B30+'(12)'!B30 | C30: Appartement incl. publiek laden | F30: 4.2 | H30: =F30*B30 | J30: =F30*0.23*3*B30
C32: Type 7: Laag- of hoogbouw met alternatieve verwarmingscomponenten (toeslag)
C33: Aantal * elektrisch vermogen verwarmingscomponent * gelijktijdigheidsfactor tabel type 7 | H33: =J33*1000/(3*230) | J33: ='(1)'!J33+'(2)'!J33+'(3)'!J33+'(4)'!J33+'(5)'!J33+'(6)'!J33+'(7)'!J33+'(8)'!J33+'(9)'!J33+'(10)'!J33+'(11)'!J33+'(12)'!J33
C35: Type 8: Kleinzakelijk (niet-huishoudelijk t/m 3x80A)
B36: ='(1)'!B36+'(2)'!B36+'(3)'!B36+'(4)'!B36+'(5)'!B36+'(6)'!B36+'(7)'!B36+'(8)'!B36+'(9)'!B36+'(10)'!B36+'(11)'!B36+'(12)'!B36 | C36: Huidige aansluitwaarde: < 3x35A | D36: G4, G6, geen of ander gas | F36: 8.7 | G36: 8.7 | H36: =F36*B36 | I36: =G36*B36 | J36: =F36*0.23*3*B36 | K36: =G36*0.23*3*B36
B37: ='(1)'!B37+'(2)'!B37+'(3)'!B37+'(4)'!B37+'(5)'!B37+'(6)'!B37+'(7)'!B37+'(8)'!B37+'(9)'!B37+'(10)'!B37+'(11)'!B37+'(12)'!B37 | C37: Huidige aansluitwaarde: < 3x35A | D37: G10 t/m G25 | F37: 44 | G37: 44 | H37: =F37*B37 | I37: =G37*B37 | J37: =F37*0.23*3*B37 | K37: =G37*0.23*3*B37
B38: ='(1)'!B38+'(2)'!B38+'(3)'!B38+'(4)'!B38+'(5)'!B38+'(6)'!B38+'(7)'!B38+'(8)'!B38+'(9)'!B38+'(10)'!B38+'(11)'!B38+'(12)'!B38 | C38: Huidige aansluitwaarde: < 3x35A | D38: > G25 | F38: 210 | G38: 210 | H38: =F38*B38 | I38: =G38*B38 | J38: =F38*0.23*3*B38 | K38: =G38*0.23*3*B38
B39: ='(1)'!B39+'(2)'!B39+'(3)'!B39+'(4)'!B39+'(5)'!B39+'(6)'!B39+'(7)'!B39+'(8)'!B39+'(9)'!B39+'(10)'!B39+'(11)'!B39+'(12)'!B39 | C39: Huidige aansluitwaarde: 3x35A t/m 3x40A | D39: G4, G6, geen of ander gas | F39: 32 | G39: 32 | H39: =F39*B39 | I39: =G39*B39 | J39: =F39*0.23*3*B39 | K39: =G39*0.23*3*B39
B40: ='(1)'!B40+'(2)'!B40+'(3)'!B40+'(4)'!B40+'(5)'!B40+'(6)'!B40+'(7)'!B40+'(8)'!B40+'(9)'!B40+'(10)'!B40+'(11)'!B40+'(12)'!B40 | C40: Huidige aansluitwaarde: 3x35A t/m 3x40A | D40: G10 t/m G25 | F40: 65 | G40: 65 | H40: =F40*B40 | I40: =G40*B40 | J40: =F40*0.23*3*B40 | K40: =G40*0.23*3*B40
B41: ='(1)'!B41+'(2)'!B41+'(3)'!B41+'(4)'!B41+'(5)'!B41+'(6)'!B41+'(7)'!B41+'(8)'!B41+'(9)'!B41+'(10)'!B41+'(11)'!B41+'(12)'!B41 | C41: Huidige aansluitwaarde: 3x35A t/m 3x40A | D41: > G25 | F41: 210 | G41: 210 | H41: =F41*B41 | I41: =G41*B41 | J41: =F41*0.23*3*B41 | K41: =G41*0.23*3*B41
B42: ='(1)'!B42+'(2)'!B42+'(3)'!B42+'(4)'!B42+'(5)'!B42+'(6)'!B42+'(7)'!B42+'(8)'!B42+'(9)'!B42+'(10)'!B42+'(11)'!B42+'(12)'!B42 | C42: Huidige aansluitwaarde: 3x50A | D42: G4, G6, geen of ander gas | F42: 44 | G42: 44 | H42: =F42*B42 | I42: =G42*B42 | J42: =F42*0.23*3*B42 | K42: =G42*0.23*3*B42
B43: ='(1)'!B43+'(2)'!B43+'(3)'!B43+'(4)'!B43+'(5)'!B43+'(6)'!B43+'(7)'!B43+'(8)'!B43+'(9)'!B43+'(10)'!B43+'(11)'!B43+'(12)'!B43 | C43: Huidige aansluitwaarde: 3x50A | D43: G10 t/m G25 | F43: 65 | G43: 65 | H43: =F43*B43 | I43: =G43*B43 | J43: =F43*0.23*3*B43 | K43: =G43*0.23*3*B43
B44: ='(1)'!B44+'(2)'!B44+'(3)'!B44+'(4)'!B44+'(5)'!B44+'(6)'!B44+'(7)'!B44+'(8)'!B44+'(9)'!B44+'(10)'!B44+'(11)'!B44+'(12)'!B44 | C44: Huidige aansluitwaarde: 3x50A | D44: > G25 | F44: 210 | G44: 210 | H44: =F44*B44 | I44: =G44*B44 | J44: =F44*0.23*3*B44 | K44: =G44*0.23*3*B44
B45: ='(1)'!B45+'(2)'!B45+'(3)'!B45+'(4)'!B45+'(5)'!B45+'(6)'!B45+'(7)'!B45+'(8)'!B45+'(9)'!B45+'(10)'!B45+'(11)'!B45+'(12)'!B45 | C45: Huidige aansluitwaarde: 3x63A | D45: G4, G6, geen of ander gas | F45: 51 | G45: 51 | H45: =F45*B45 | I45: =G45*B45 | J45: =F45*0.23*3*B45 | K45: =G45*0.23*3*B45
B46: ='(1)'!B46+'(2)'!B46+'(3)'!B46+'(4)'!B46+'(5)'!B46+'(6)'!B46+'(7)'!B46+'(8)'!B46+'(9)'!B46+'(10)'!B46+'(11)'!B46+'(12)'!B46 | C46: Huidige aansluitwaarde: 3x63A | D46: G10 t/m G25 | F46: 138 | G46: 138 | H46: =F46*B46 | I46: =G46*B46 | J46: =F46*0.23*3*B46 | K46: =G46*0.23*3*B46
B47: ='(1)'!B47+'(2)'!B47+'(3)'!B47+'(4)'!B47+'(5)'!B47+'(6)'!B47+'(7)'!B47+'(8)'!B47+'(9)'!B47+'(10)'!B47+'(11)'!B47+'(12)'!B47 | C47: Huidige aansluitwaarde: 3x63A | D47: > G25 | F47: 210 | G47: 210 | H47: =F47*B47 | I47: =G47*B47 | J47: =F47*0.23*3*B47 | K47: =G47*0.23*3*B47
...

Sheet Blad1

Sheet (1)
A1: Vul alleen de | C1: vlakken in. | F1: Ontwerpstroom kabel | O1: Verschillende doorsnedes in dezelfde kabelgroep! Let op: Alleen de gele velden zijn invoervelden ! | AD1: Invoervelden
B2: Aantal van eenheid | C2: Type wooneenheid | F2: Ontwerpstroom verbruik per eenheid | G2: Ontwerpstroom opwek per eenheid | H2: Totaal verbruik op kabelniveau in A | I2: Totaal opwek op kabelniveau in A | J2: Totaal verbruik op kabelniveau in kW | K2: Totaal opwek op kabelniveau in kW | M2: Opmerkingen | O2: Evenredig verdeelde belasting over de kabel (50%), gebaseerd op tabellen 6 en 8 uit kader Eea-0205.K
O3: Er moet wel sprake zijn van zogenaamde kabelverjonging, d.w.z. de zwaardere kabels aan het begin van de kabelgroep en de dunnere kabels op het eind van de kabelgroep.
C4: Type 1: Laagbouw huishoudens t/m bouwjaar 2021 met een individuele warmtepomp en tapwaterbuffer
B5: 2 | C5: Vrijstaand | F5: 8.1 | G5: 9.2 | H5: =F5*B5 | I5: =G5*B5 | J5: =F5*0.23*3*B5 | K5: =G5*0.23*3*B5
C6: Twee onder een kap | F6: 7.1 | G6: 7 | H6: =F6*B6 | I6: =G6*B6 | J6: =F6*0.23*3*B6 | K6: =G6*0.23*3*B6
C7: Rijtjeswoning (woonboten, woonwagens, chalets en vakantiehuisjes) | F7: 6.4 | G7: 5.9 | H7: =F7*B7 | I7: =G7*B7 | J7: =F7*0.23*3*B7 | K7: =G7*0.23*3*B7
C8: Onbekend | F8: 6.8 | G8: 5.9 | H8: =F8*B8 | I8: =G8*B8 | J8: =F8*0.23*3*B8 | K8: =G8*0.23*3*B8
C10: Type 2: Laagbouw huishoudens met stads- of gasverwarming
C11: Vrijstaand | F11: 3.9 | G11: 8.9 | H11: =F11*B11 | I11: =G11*B11 | J11: =F11*0.23*3*B11 | K11: =G11*0.23*3*B11
C12: Twee onder een kap | F12: 3.9 | G12: 6.8 | H12: =F12*B12 | I12: =G12*B12 | J12: =F12*0.23*3*B12 | K12: =G12*0.23*3*B12 | O12: ontwerpstroom | W12: t/m 57A | X12: t/m 72A | Y12: t/m 90A | Z12: t/m 113A | AA12: t/m 144A | AB12: t/m 180A | AC12: t/m 225A
C13: Rijtjeswoning (woonboten, woonwagens, chalets en vakantiehuisjes) | F13: 3.9 | G13: 5.7 | H13: =F13*B13 | I13: =G13*B13 | J13: =F13*0.23*3*B13 | K13: =G13*0.23*3*B13 | O13: smeltveiligheid Inom | W13: 63A | X13: 80A | Y13: 100A | Z13: 125A | AA13: 160A | AB13: 200A | AC13: 250A | AD13: invoer
C14: Onbekend | F14: 3.9 | G14: 5.7 | H14: =F14*B14 | I14: =G14*B14 | J14: =F14*0.23*3*B14 | K14: =G14*0.23*3*B14 | P14: waarden per 1000m | S14: waarden o.b.v. kabellengte | W14: 63 | X14: 80 | Y14: 100 | Z14: 125 | AA14: 160 | AB14: 200 | AC14: 250 | AD14: kabellengtes
P15: ohm | Q15: ohm | R15: ohm | S15: ohm | T15: ohm | U15: ohm | V15: A | W15: ohm | X15: ohm | Y15: ohm | Z15: ohm | AA15: ohm | AB15: ohm | AC15: ohm | AD15: per doorsnede
C16: Type 3: Laagbouw huishoudens vanaf bouwjaar 2022 met een individuele warmtepomp en tapwaterbuffer | W16: 0.25 | X16: 0.25 | Y16: 0.204 | Z16: 0.163 | AA16: 0.128 | AB16: 0.092 | AC16: 0.062
C17: Vrijstaand | F17: 7.54 | G17: 9.2 | H17: =F17*B17 | I17: =G17*B17 | J17: =F17*0.23*3*B17 | K17: =G17*0.23*3*B17 | O17: Name | P17: R | Q17: X | R17: Z (berekend) | S17: R | T17: X | U17: Z (berekend) | W17: 0.25 | X17: 0.25 | Y17: 0.25 | Z17: 0.25 | AA17: 0.25 | AB17: 0.218 | AC17: 0.171 | AD17: in meters | AI17: hulptabel
C18: Twee onder een kap | F18: 6.8 | G18: 7 | H18: =F18*B18 | I18: =G18*B18 | J18: =F18*0.23*3*B18 | K18: =G18*0.23*3*B18 | O18: 4*240mm2 Al | P18: 0.129 | Q18: 0.073 | R18: =SQRT(P18^2+Q18^2) | S18: =+P18*AD18/1000 | T18: =+AD18*Q18/1000 | V18: 359 | W18: =IF(W14<=V18+3,+AD18,"X") | X18: =IF(X14<=V18+3,+AD18,"X") | Y18: =IF(Y14<=V18+3,+AD18,"X") | Z18: =IF(Z14<=V18+3,+AD18,"X") | AA18: =IF(AA14<=V18+3,+AD18,"X") | AB18: =IF(AB14<=V18+3,+AD18,"X") | AC18: =IF(AC14<=V18+3,+AD18,"X") | AE18: 4*240mm2 Al | AG18: =IF(OR(W18=AD18,AND(AD18=0,W18="X")),"OK","niet OK") | AH18: =IF(OR(X18=AD18,AND(AD18=0,X18="X")),"OK","niet OK") | AI18: =IF(OR(Y18=AD18,AND(AD18=0,Y18="X")),"OK","niet OK") | AJ18: =IF(OR(Z18=AD18,AND(AD18=0,Z18="X")),"OK","niet OK") | AK18: =IF(OR(AA18=AD18,AND(AD18=0,AA18="X")),"OK","niet OK") | AL18: =IF(OR(AB18=AD18,AND(AD18=0,AB18="X")),"OK","niet OK") | AM18: =IF(OR(AC18=AD18,AND(AD18=0,AC18="X")),"OK","niet OK")
C19: Rijtjeswoning | F19: 6.3 | G19: 5.9 | H19: =F19*B19 | I19: =G19*B19 | J19: =F19*0.23*3*B19 | K19: =G19*0.23*3*B19 | O19: 4*150mm2 Al | P19: 0.206 | Q19: 0.079 | R19: =SQRT(P19^2+Q19^2) | S19: =+P19*AD19/1000 | T19: =+AD19*Q19/1000 | V19: 272 | W19: =IF(W14<=V19+3,+AD19,"X") | X19: =IF(X14<=V19+3,+AD19,"X") | Y19: =IF(Y14<=V19+3,+AD19,"X") | Z19: =IF(Z14<=V19+3,+AD19,"X") | AA19: =IF(AA14<=V19+3,+AD19,"X") | AB19: =IF(AB14<=V19+3,+AD19,"X") | AC19: =IF(AC14<=V19+3,+AD19,"X") | AD19: 100 | AE19: 4*150mm2 Al | AG19: =IF(OR(W19=AD19,AND(AD19=0,W19="X")),"OK","niet OK") | AH19: =IF(OR(X19=AD19,AND(AD19=0,X19="X")),"OK","niet OK") | AI19: =IF(OR(Y19=AD19,AND(AD19=0,Y19="X")),"OK","niet OK") | AJ19: =IF(OR(Z19=AD19,AND(AD19=0,Z19="X")),"OK","niet OK") | AK19: =IF(OR(AA19=AD19,AND(AD19=0,AA19="X")),"OK","niet OK") | AL19: =IF(OR(AB19=AD19,AND(AD19=0,AB19="X")),"OK","niet OK") | AM19: =IF(OR(AC19=AD19,AND(AD19=0,AC19="X")),"OK","niet OK")
C20: Onbekend | F20: 6.4 | G20: 5.9 | H20: =F20*B20 | I20: =G20*B20 | J20: =F20*0.23*3*B20 | K20: =G20*0.23*3*B20 | O20: 4*120mm2 Al | P20: 0.281 | Q20: 0.081 | R20: =SQRT(P20^2+Q20^2) | S20: =+P20*AD20/1000 | T20: =+AD20*Q20/1000 | V20: 243 | W20: =IF(W14<=V20+3,+AD20,"X") | X20: =IF(X14<=V20+3,+AD20,"X") | Y20: =IF(Y14<=V20+3,+AD20,"X") | Z20: =IF(Z14<=V20+3,+AD20,"X") | AA20: =IF(AA14<=V20+3,+AD20,"X") | AB20: =IF(AB14<=V20+3,+AD20,"X") | AC20: =IF(AC14<=V20+3,+AD20,"X") | AE20: 4*120mm2 Al | AG20: =IF(OR(W20=AD20,AND(AD20=0,W20="X")),"OK","niet OK") | AH20: =IF(OR(X20=AD20,AND(AD20=0,X20="X")),"OK","niet OK") | AI20: =IF(OR(Y20=AD20,AND(AD20=0,Y20="X")),"OK","niet OK") | AJ20: =IF(OR(Z20=AD20,AND(AD20=0,Z20="X")),"OK","niet OK") | AK20: =IF(OR(AA20=AD20,AND(AD20=0,AA20="X")),"OK","niet OK") | AL20: =IF(OR(AB20=AD20,AND(AD20=0,AB20="X")),"OK","niet OK") | AM20: =IF(OR(AC20=AD20,AND(AD20=0,AC20="X")),"OK","niet OK")
O21: 4*95mm2 Al | P21: 0.32 | Q21: 0.082 | R21: =SQRT(P21^2+Q21^2) | S21: =+P21*AD21/1000 | T21: =+AD21*Q21/1000 | V21: 213 | W21: =IF(W14<=V21+3,+AD21,"X") | X21: =IF(X14<=V21+3,+AD21,"X") | Y21: =IF(Y14<=V21+3,+AD21,"X") | Z21: =IF(Z14<=V21+3,+AD21,"X") | AA21: =IF(AA14<=V21+3,+AD21,"X") | AB21: =IF(AB14<=V21+3,+AD21,"X") | AC21: =IF(AC14<=V21+3,+AD21,"X") | AE21: 4*95mm2 Al | AG21: =IF(OR(W21=AD21,AND(AD21=0,W21="X")),"OK","niet OK") | AH21: =IF(OR(X21=AD21,AND(AD21=0,X21="X")),"OK","niet OK") | AI21: =IF(OR(Y21=AD21,AND(AD21=0,Y21="X")),"OK","niet OK") | AJ21: =IF(OR(Z21=AD21,AND(AD21=0,Z21="X")),"OK","niet OK") | AK21: =IF(OR(AA21=AD21,AND(AD21=0,AA21="X")),"OK","niet OK") | AL21: =IF(OR(AB21=AD21,AND(AD21=0,AB21="X")),"OK","niet OK") | AM21: =IF(OR(AC21=AD21,AND(AD21=0,AC21="X")),"OK","niet OK")
C22: Type 4: Hoogbouw huishoudens met collectieve warmtepomp, stads- of gasverwarming | O22: 4*70mm2 Al | P22: 0.443 | Q22: =(Q21+Q23)/2 | R22: =SQRT(P22^2+Q22^2) | S22: =+P22*AD22/1000 | T22: =+AD22*Q22/1000 | V22: 177 | W22: =IF(W14<=V22+3,+AD22,"X") | X22: =IF(X14<=V22+3,+AD22,"X") | Y22: =IF(Y14<=V22+3,+AD22,"X") | Z22: =IF(Z14<=V22+3,+AD22,"X") | AA22: =IF(AA14<=V22+3,+AD22,"X") | AB22: =IF(AB14<=V22+3,+AD22,"X") | AC22: =IF(AC14<=V22+3,+AD22,"X") | AE22: 4*70mm2 Al | AG22: =IF(OR(W22=AD22,AND(AD22=0,W22="X")),"OK","niet OK") | AH22: =IF(OR(X22=AD22,AND(AD22=0,X22="X")),"OK","niet OK") | AI22: =IF(OR(Y22=AD22,AND(AD22=0,Y22="X")),"OK","niet OK") | AJ22: =IF(OR(Z22=AD22,AND(AD22=0,Z22="X")),"OK","niet OK") | AK22: =IF(OR(AA22=AD22,AND(AD22=0,AA22="X")),"OK","niet OK") | AL22: =IF(OR(AB22=AD22,AND(AD22=0,AB22="X")),"OK","niet OK") | AM22: =IF(OR(AC22=AD22,AND(AD22=0,AC22="X")),"OK","niet OK")
C23: Appartement incl. publiek laden | F23: 3.4 | H23: =F23*B23 | J23: =F23*0.23*3*B23 | O23: 4*50mm2 Al | P23: 0.641 | Q23: 0.085 | R23: =SQRT(P23^2+Q23^2) | S23: =+P23*AD23/1000 | T23: =+AD23*Q23/1000 | V23: 144 | W23: =IF(W14<=V23+3,+AD23,"X") | X23: =IF(X14<=V23+3,+AD23,"X") | Y23: =IF(Y14<=V23+3,+AD23,"X") | Z23: =IF(Z14<=V23+3,+AD23,"X") | AA23: =IF(AA14<=V23+3,+AD23,"X") | AB23: =IF(AB14<=V23+3,+AD23,"X") | AC23: =IF(AC14<=V23+3,+AD23,"X") | AE23: 4*50mm2 Al | AG23: =IF(OR(W23=AD23,AND(AD23=0,W23="X")),"OK","niet OK") | AH23: =IF(OR(X23=AD23,AND(AD23=0,X23="X")),"OK","niet OK") | AI23: =IF(OR(Y23=AD23,AND(AD23=0,Y23="X")),"OK","niet OK") | AJ23: =IF(OR(Z23=AD23,AND(AD23=0,Z23="X")),"OK","niet OK") | AK23: =IF(OR(AA23=AD23,AND(AD23=0,AA23="X")),"OK","niet OK") | AL23: =IF(OR(AB23=AD23,AND(AD23=0,AB23="X")),"OK","niet OK") | AM23: =IF(OR(AC23=AD23,AND(AD23=0,AC23="X")),"OK","niet OK")
C24: Collectieve warmtepomp - elektrisch vermogen | H24: =J24*1000/(3*230) | J24: 0 | O24: 4*35mm2 Al | P24: 0.868 | Q24: 0.101 | R24: =SQRT(P24^2+Q24^2) | S24: =+P24*AD24/1000 | T24: =+AD24*Q24/1000 | V24: 120 | W24: =IF(W14<=V24+3,+AD24,"X") | X24: =IF(X14<=V24+3,+AD24,"X") | Y24: =IF(Y14<=V24+3,+AD24,"X") | Z24: =IF(Z14<=V24+3,+AD24,"X") | AA24: =IF(AA14<=V24+3,+AD24,"X") | AB24: =IF(AB14<=V24+3,+AD24,"X") | AC24: =IF(AC14<=V24+3,+AD24,"X") | AE24: 4*35mm2 Al | AG24: =IF(OR(W24=AD24,AND(AD24=0,W24="X")),"OK","niet OK") | AH24: =IF(OR(X24=AD24,AND(AD24=0,X24="X")),"OK","niet OK") | AI24: =IF(OR(Y24=AD24,AND(AD24=0,Y24="X")),"OK","niet OK") | AJ24: =IF(OR(Z24=AD24,AND(AD24=0,Z24="X")),"OK","niet OK") | AK24: =IF(OR(AA24=AD24,AND(AD24=0,AA24="X")),"OK","niet OK") | AL24: =IF(OR(AB24=AD24,AND(AD24=0,AB24="X")),"OK","niet OK") | AM24: =IF(OR(AC24=AD24,AND(AD24=0,AC24="X")),"OK","niet OK")
O25: 4*25mm2 Al | P25: 1.2 | Q25: 0.094 | R25: =SQRT(P25^2+Q25^2) | S25: =+P25*AD25/1000 | T25: =+AD25*Q25/1000 | V25: 100 | W25: =IF(W14<=V25+3,+AD25,"X") | X25: =IF(X14<=V25+3,+AD25,"X") | Y25: =IF(Y14<=V25+3,+AD25,"X") | Z25: =IF(Z14<=V25+3,+AD25,"X") | AA25: =IF(AA14<=V25+3,+AD25,"X") | AB25: =IF(AB14<=V25+3,+AD25,"X") | AC25: =IF(AC14<=V25+3,+AD25,"X") | AE25: 4*25mm2 Al | AG25: =IF(OR(W25=AD25,AND(AD25=0,W25="X")),"OK","niet OK") | AH25: =IF(OR(X25=AD25,AND(AD25=0,X25="X")),"OK","niet OK") | AI25: =IF(OR(Y25=AD25,AND(AD25=0,Y25="X")),"OK","niet OK") | AJ25: =IF(OR(Z25=AD25,AND(AD25=0,Z25="X")),"OK","niet OK") | AK25: =IF(OR(AA25=AD25,AND(AD25=0,AA25="X")),"OK","niet OK") | AL25: =IF(OR(AB25=AD25,AND(AD25=0,AB25="X")),"OK","niet OK") | AM25: =IF(OR(AC25=AD25,AND(AD25=0,AC25="X")),"OK","niet OK")
C26: Type 5: Hoogbouw huishoudens t/m bouwjaar 2021 met een individuele warmtepomp | O26: 4*16mm2 Al | P26: 1.91 | Q26: 0.096 | R26: =SQRT(P26^2+Q26^2) | S26: =+P26*AD26/1000 | T26: =+AD26*Q26/1000 | V26: 78 | W26: =IF(W14<=V26+3,+AD26,"X") | X26: =IF(X14<=V26+3,+AD26,"X") | Y26: =IF(Y14<=V26+3,+AD26,"X") | Z26: =IF(Z14<=V26+3,+AD26,"X") | AA26: =IF(AA14<=V26+3,+AD26,"X") | AB26: =IF(AB14<=V26+3,+AD26,"X") | AC26: =IF(AC14<=V26+3,+AD26,"X") | AE26: 4*16mm2 Al | AG26: =IF(OR(W26=AD26,AND(AD26=0,W26="X")),"OK","niet OK") | AH26: =IF(OR(X26=AD26,AND(AD26=0,X26="X")),"OK","niet OK") | AI26: =IF(OR(Y26=AD26,AND(AD26=0,Y26="X")),"OK","niet OK") | AJ26: =IF(OR(Z26=AD26,AND(AD26=0,Z26="X")),"OK","niet OK") | AK26: =IF(OR(AA26=AD26,AND(AD26=0,AA26="X")),"OK","niet OK") | AL26: =IF(OR(AB26=AD26,AND(AD26=0,AB26="X")),"OK","niet OK") | AM26: =IF(OR(AC26=AD26,AND(AD26=0,AC26="X")),"OK","niet OK")
C27: Appartement incl. publiek laden | F27: 5.4 | H27: =F27*B27 | J27: =F27*0.23*3*B27
O28: 4*185mm2 Cu | P28: 0.107 | Q28: 0.068 | R28: =SQRT(P28^2+Q28^2) | S28: =+P28*AD28/1000 | T28: =+AD28*Q28/1000 | V28: 393 | W28: =IF(W14<=V28+3,+AD28,"X") | X28: =IF(X14<=V28+3,+AD28,"X") | Y28: =IF(Y14<=V28+3,+AD28,"X") | Z28: =IF(Z14<=V28+3,+AD28,"X") | AA28: =IF(AA14<=V28+3,+AD28,"X") | AB28: =IF(AB14<=V28+3,+AD28,"X") | AC28: =IF(AC14<=V28+3,+AD28,"X") | AE28: 4*185mm2 Cu | AG28: =IF(OR(W28=AD28,AND(AD28=0,W28="X")),"OK","niet OK") | AH28: =IF(OR(X28=AD28,AND(AD28=0,X28="X")),"OK","niet OK") | AI28: =IF(OR(Y28=AD28,AND(AD28=0,Y28="X")),"OK","niet OK") | AJ28: =IF(OR(Z28=AD28,AND(AD28=0,Z28="X")),"OK","niet OK") | AK28: =IF(OR(AA28=AD28,AND(AD28=0,AA28="X")),"OK","niet OK") | AL28: =IF(OR(AB28=AD28,AND(AD28=0,AB28="X")),"OK","niet OK") | AM28: =IF(OR(AC28=AD28,AND(AD28=0,AC28="X")),"OK","niet OK")
C29: Type 6: Nieuwbouw hoogbouw huishoudens vanaf bouwjaar 2022 met een individuele warmtepomp | O29: 4*150mm2 Cu | P29: 0.125 | Q29: 0.068 | R29: =SQRT(P29^2+Q29^2) | S29: =+P29*AD29/1000 | T29: =+AD29*Q29/1000 | V29: 348 | W29: =IF(W14<=V29+3,+AD29,"X") | X29: =IF(X14<=V29+3,+AD29,"X") | Y29: =IF(Y14<=V29+3,+AD29,"X") | Z29: =IF(Z14<=V29+3,+AD29,"X") | AA29: =IF(AA14<=V29+3,+AD29,"X") | AB29: =IF(AB14<=V29+3,+AD29,"X") | AC29: =IF(AC14<=V29+3,+AD29,"X") | AE29: 4*150mm2 Cu | AG29: =IF(OR(W29=AD29,AND(AD29=0,W29="X")),"OK","niet OK") | AH29: =IF(OR(X29=AD29,AND(AD29=0,X29="X")),"OK","niet OK") | AI29: =IF(OR(Y29=AD29,AND(AD29=0,Y29="X")),"OK","niet OK") | AJ29: =IF(OR(Z29=AD29,AND(AD29=0,Z29="X")),"OK","niet OK") | AK29: =IF(OR(AA29=AD29,AND(AD29=0,AA29="X")),"OK","niet OK") | AL29: =IF(OR(AB29=AD29,AND(AD29=0,AB29="X")),"OK","niet OK") | AM29: =IF(OR(AC29=AD29,AND(AD29=0,AC29="X")),"OK","niet OK")
C30: Appartement incl. publiek laden | F30: 5.1 | H30: =F30*B30 | J30: =F30*0.23*3*B30 | O30: 4*120mm2 Cu | P30: 0.152 | Q30: 0.069 | R30: 0.16692813 | S30: =+P30*AD30/1000 | T30: =+AD30*Q30/1000 | V30: 307 | W30: =IF(W14<=V30+3,+AD30,"X") | X30: =IF(X14<=V30+3,+AD30,"X") | Y30: =IF(Y14<=V30+3,+AD30,"X") | Z30: =IF(Z14<=V30+3,+AD30,"X") | AA30: =IF(AA14<=V30+3,+AD30,"X") | AB30: =IF(AB14<=V30+3,+AD30,"X") | AC30: =IF(AC14<=V30+3,+AD30,"X") | AE30: 4*120mm2 Cu | AG30: =IF(OR(W30=AD30,AND(AD30=0,W30="X")),"OK","niet OK") | AH30: =IF(OR(X30=AD30,AND(AD30=0,X30="X")),"OK","niet OK") | AI30: =IF(OR(Y30=AD30,AND(AD30=0,Y30="X")),"OK","niet OK") | AJ30: =IF(OR(Z30=AD30,AND(AD30=0,Z30="X")),"OK","niet OK") | AK30: =IF(OR(AA30=AD30,AND(AD30=0,AA30="X")),"OK","niet OK") | AL30: =IF(OR(AB30=AD30,AND(AD30=0,AB30="X")),"OK","niet OK") | AM30: =IF(OR(AC30=AD30,AND(AD30=0,AC30="X")),"OK","niet OK")
O31: 4*95mm2 Cu | P31: 0.194 | Q31: 0.069 | R31: =SQRT(P31^2+Q31^2) | S31: =+P31*AD31/1000 | T31: =+AD31*Q31/1000 | V31: 272 | W31: =IF(W14<=V31+3,+AD31,"X") | X31: =IF(X14<=V31+3,+AD31,"X") | Y31: =IF(Y14<=V31+3,+AD31,"X") | Z31: =IF(Z14<=V31+3,+AD31,"X") | AA31: =IF(AA14<=V31+3,+AD31,"X") | AB31: =IF(AB14<=V31+3,+AD31,"X") | AC31: =IF(AC14<=V31+3,+AD31,"X") | AE31: 4*95mm2 Cu | AG31: =IF(OR(W31=AD31,AND(AD31=0,W31="X")),"OK","niet OK") | AH31: =IF(OR(X31=AD31,AND(AD31=0,X31="X")),"OK","niet OK") | AI31: =IF(OR(Y31=AD31,AND(AD31=0,Y31="X")),"OK","niet OK") | AJ31: =IF(OR(Z31=AD31,AND(AD31=0,Z31="X")),"OK","niet OK") | AK31: =IF(OR(AA31=AD31,AND(AD31=0,AA31="X")),"OK","niet OK") | AL31: =IF(OR(AB31=AD31,AND(AD31=0,AB31="X")),"OK","niet OK") | AM31: =IF(OR(AC31=AD31,AND(AD31=0,AC31="X")),"OK","niet OK")
C32: Type 7: Laag- of hoogbouw met alternatieve verwarmingscomponenten (toeslag) | O32: 4*70mm2 Cu | P32: 0.268 | Q32: 0.072 | R32: =SQRT(P32^2+Q32^2) | S32: =+P32*AD32/1000 | T32: =+AD32*Q32/1000 | V32: 227 | W32: =IF(W14<=V32+3,+AD32,"X") | X32: =IF(X14<=V32+3,+AD32,"X") | Y32: =IF(Y14<=V32+3,+AD32,"X") | Z32: =IF(Z14<=V32+3,+AD32,"X") | AA32: =IF(AA14<=V32+3,+AD32,"X") | AB32: =IF(AB14<=V32+3,+AD32,"X") | AC32: =IF(AC14<=V32+3,+AD32,"X") | AE32: 4*70mm2 Cu | AG32: =IF(OR(W32=AD32,AND(AD32=0,W32="X")),"OK","niet OK") | AH32: =IF(OR(X32=AD32,AND(AD32=0,X32="X")),"OK","niet OK") | AI32: =IF(OR(Y32=AD32,AND(AD32=0,Y32="X")),"OK","niet OK") | AJ32: =IF(OR(Z32=AD32,AND(AD32=0,Z32="X")),"OK","niet OK") | AK32: =IF(OR(AA32=AD32,AND(AD32=0,AA32="X")),"OK","niet OK") | AL32: =IF(OR(AB32=AD32,AND(AD32=0,AB32="X")),"OK","niet OK") | AM32: =IF(OR(AC32=AD32,AND(AD32=0,AC32="X")),"OK","niet OK")
C33: Aantal * elektrisch vermogen verwarmingscomponent * gelijktijdigheidsfactor tabel type 7 | H33: =J33*1000/(3*230) | O33: 4*50mm2 Cu | P33: 0.387 | Q33: 0.085 | R33: =SQRT(P33^2+Q33^2) | S33: =+P33*AD33/1000 | T33: =+AD33*Q33/1000 | V33: 182 | W33: =IF(W14<=V33+3,+AD33,"X") | X33: =IF(X14<=V33+3,+AD33,"X") | Y33: =IF(Y14<=V33+3,+AD33,"X") | Z33: =IF(Z14<=V33+3,+AD33,"X") | AA33: =IF(AA14<=V33+3,+AD33,"X") | AB33: =IF(AB14<=V33+3,+AD33,"X") | AC33: =IF(AC14<=V33+3,+AD33,"X") | AE33: 4*50mm2 Cu | AG33: =IF(OR(W33=AD33,AND(AD33=0,W33="X")),"OK","niet OK") | AH33: =IF(OR(X33=AD33,AND(AD33=0,X33="X")),"OK","niet OK") | AI33: =IF(OR(Y33=AD33,AND(AD33=0,Y33="X")),"OK","niet OK") | AJ33: =IF(OR(Z33=AD33,AND(AD33=0,Z33="X")),"OK","niet OK") | AK33: =IF(OR(AA33=AD33,AND(AD33=0,AA33="X")),"OK","niet OK") | AL33: =IF(OR(AB33=AD33,AND(AD33=0,AB33="X")),"OK","niet OK") | AM33: =IF(OR(AC33=AD33,AND(AD33=0,AC33="X")),"OK","niet OK")
O34: 4*35mm2 Cu | P34: 0.524 | Q34: 0.1 | R34: =SQRT(P34^2+Q34^2) | S34: =+P34*AD34/1000 | T34: =+AD34*Q34/1000 | V34: 154 | W34: =IF(W14<=V34+3,+AD34,"X") | X34: =IF(X14<=V34+3,+AD34,"X") | Y34: =IF(Y14<=V34+3,+AD34,"X") | Z34: =IF(Z14<=V34+3,+AD34,"X") | AA34: =IF(AA14<=V34+3,+AD34,"X") | AB34: =IF(AB14<=V34+3,+AD34,"X") | AC34: =IF(AC14<=V34+3,+AD34,"X") | AE34: 4*35mm2 Cu | AG34: =IF(OR(W34=AD34,AND(AD34=0,W34="X")),"OK","niet OK") | AH34: =IF(OR(X34=AD34,AND(AD34=0,X34="X")),"OK","niet OK") | AI34: =IF(OR(Y34=AD34,AND(AD34=0,Y34="X")),"OK","niet OK") | AJ34: =IF(OR(Z34=AD34,AND(AD34=0,Z34="X")),"OK","niet OK") | AK34: =IF(OR(AA34=AD34,AND(AD34=0,AA34="X")),"OK","niet OK") | AL34: =IF(OR(AB34=AD34,AND(AD34=0,AB34="X")),"OK","niet OK") | AM34: =IF(OR(AC34=AD34,AND(AD34=0,AC34="X")),"OK","niet OK")
C35: Type 8: Kleinzakelijk (niet-huishoudelijk t/m 3x80A) | O35: 4*25mm2 Cu | P35: 0.727 | Q35: 0.094 | R35: =SQRT(P35^2+Q35^2) | S35: =+P35*AD35/1000 | T35: =+AD35*Q35/1000 | V35: 128 | W35: =IF(W14<=V35+3,+AD35,"X") | X35: =IF(X14<=V35+3,+AD35,"X") | Y35: =IF(Y14<=V35+3,+AD35,"X") | Z35: =IF(Z14<=V35+3,+AD35,"X") | AA35: =IF(AA14<=V35+3,+AD35,"X") | AB35: =IF(AB14<=V35+3,+AD35,"X") | AC35: =IF(AC14<=V35+3,+AD35,"X") | AE35: 4*25mm2 Cu | AG35: =IF(OR(W35=AD35,AND(AD35=0,W35="X")),"OK","niet OK") | AH35: =IF(OR(X35=AD35,AND(AD35=0,X35="X")),"OK","niet OK") | AI35: =IF(OR(Y35=AD35,AND(AD35=0,Y35="X")),"OK","niet OK") | AJ35: =IF(OR(Z35=AD35,AND(AD35=0,Z35="X")),"OK","niet OK") | AK35: =IF(OR(AA35=AD35,AND(AD35=0,AA35="X")),"OK","niet OK") | AL35: =IF(OR(AB35=AD35,AND(AD35=0,AB35="X")),"OK","niet OK") | AM35: =IF(OR(AC35=AD35,AND(AD35=0,AC35="X")),"OK","niet OK")
C36: Huidige aansluitwaarde: < 3x35A | D36: G4, G6, geen of ander gas | F36: 8.7 | G36: 8.7 | H36: =F36*B36 | I36: =G36*B36 | J36: =F36*0.23*3*B36 | K36: =G36*0.23*3*B36 | O36: 4*16mm2 Cu | P36: 1.15 | Q36: 0.097 | R36: =SQRT(P36^2+Q36^2) | S36: =+P36*AD36/1000 | T36: =+AD36*Q36/1000 | V36: 99 | W36: =IF(W14<=V36+3,+AD36,"X") | X36: =IF(X14<=V36+3,+AD36,"X") | Y36: =IF(Y14<=V36+3,+AD36,"X") | Z36: =IF(Z14<=V36+3,+AD36,"X") | AA36: =IF(AA14<=V36+3,+AD36,"X") | AB36: =IF(AB14<=V36+3,+AD36,"X") | AC36: =IF(AC14<=V36+3,+AD36,"X") | AE36: 4*16mm2 Cu | AG36: =IF(OR(W36=AD36,AND(AD36=0,W36="X")),"OK","niet OK") | AH36: =IF(OR(X36=AD36,AND(AD36=0,X36="X")),"OK","niet OK") | AI36: =IF(OR(Y36=AD36,AND(AD36=0,Y36="X")),"OK","niet OK") | AJ36: =IF(OR(Z36=AD36,AND(AD36=0,Z36="X")),"OK","niet OK") | AK36: =IF(OR(AA36=AD36,AND(AD36=0,AA36="X")),"OK","niet OK") | AL36: =IF(OR(AB36=AD36,AND(AD36=0,AB36="X")),"OK","niet OK") | AM36: =IF(OR(AC36=AD36,AND(AD36=0,AC36="X")),"OK","niet OK")
C37: Huidige aansluitwaarde: < 3x35A | D37: G10 t/m G25 | F37: 44 | G37: 44 | H37: =F37*B37 | I37: =G37*B37 | J37: =F37*0.23*3*B37 | K37: =G37*0.23*3*B37
C38: Huidige aansluitwaarde: < 3x35A | D38: > G25 | F38: 65 | G38: 65 | H38: =F38*B38 | I38: =G38*B38 | J38: =F38*0.23*3*B38 | K38: =G38*0.23*3*B38 | O38: totale samengestelde impedantie | S38: =SUM(S18:S37) | T38: =SUM(T18:T37) | U38: =SQRT(S38^2+T38^2) | W38: =IF(U38<=W16,"OK","niet OK") | X38: =IF(U38<=X16,"OK","niet OK") | Y38: =IF(U38<=Y16,"OK","niet OK") | Z38: =IF(U38<=Z16,"OK","niet OK") | AA38: =IF(U38<=AA16,"OK","niet OK") | AB38: =IF(U38<=AB16,"OK","niet OK") | AC38: =IF(U38<=AC16,"OK","niet OK") | AD38: t.a.v. totale impedantie passieve trafo en gG
C39: Huidige aansluitwaarde: 3x35A t/m 3x40A | D39: G4, G6, geen of ander gas | F39: 32 | G39: 32 | H39: =F39*B39 | I39: =G39*B39 | J39: =F39*0.23*3*B39 | K39: =G39*0.23*3*B39 | W39: =IF(U38<=W17,"OK","niet OK") | X39: =IF(U38<=X17,"OK","niet OK") | Y39: =IF(U38<=Y17,"OK","niet OK") | Z39: =IF(U38<=Z17,"OK","niet OK") | AA39: =IF(U38<=AA17,"OK","niet OK") | AB39: =IF(U38<=AB17,"OK","niet OK") | AC39: =IF(U38<=AC17,"OK","niet OK") | AD39: t.a.v. totale impedantie regeltrafo en gFF
C40: Huidige aansluitwaarde: 3x35A t/m 3x40A | D40: G10 t/m G25 | F40: 65 | G40: 65 | H40: =F40*B40 | I40: =G40*B40 | J40: =F40*0.23*3*B40 | K40: =G40*0.23*3*B40 | W40: =IF(AND(AG18="OK",AG19="OK",AG20="OK",AG21="OK",AG22="OK",AG23="OK",AG24="OK",AG25="OK",AG26="OK",AG28="OK",AG29="OK",AG31="OK",AG32="OK",AG33="OK",AG34="OK",AG35="OK",AG36="OK"),"OK","niet OK") | X40: =IF(AND(AH18="OK",AH19="OK",AH20="OK",AH21="OK",AH22="OK",AH23="OK",AH24="OK",AH25="OK",AH26="OK",AH28="OK",AH29="OK",AH31="OK",AH32="OK",AH33="OK",AH34="OK",AH35="OK",AH36="OK"),"OK","niet OK") | Y40: =IF(AND(AI18="OK",AI19="OK",AI20="OK",AI21="OK",AI22="OK",AI23="OK",AI24="OK",AI25="OK",AI26="OK",AI28="OK",AI29="OK",AI31="OK",AI32="OK",AI33="OK",AI34="OK",AI35="OK",AI36="OK"),"OK","niet OK") | Z40: =IF(AND(AJ18="OK",AJ19="OK",AJ20="OK",AJ21="OK",AJ22="OK",AJ23="OK",AJ24="OK",AJ25="OK",AJ26="OK",AJ28="OK",AJ29="OK",AJ31="OK",AJ32="OK",AJ33="OK",AJ34="OK",AJ35="OK",AJ36="OK"),"OK","niet OK") | AA40: =IF(AND(AK18="OK",AK19="OK",AK20="OK",AK21="OK",AK22="OK",AK23="OK",AK24="OK",AK25="OK",AK26="OK",AK28="OK",AK29="OK",AK31="OK",AK32="OK",AK33="OK",AK34="OK",AK35="OK",AK36="OK"),"OK","niet OK") | AB40: =IF(AND(AL18="OK",AL19="OK",AL20="OK",AL21="OK",AL22="OK",AL23="OK",AL24="OK",AL25="OK",AL26="OK",AL28="OK",AL29="OK",AL31="OK",AL32="OK",AL33="OK",AL34="OK",AL35="OK",AL36="OK"),"OK","niet OK") | AC40: =IF(AND(AM18="OK",AM19="OK",AM20="OK",AM21="OK",AM22="OK",AM23="OK",AM24="OK",AM25="OK",AM26="OK",AM28="OK",AM29="OK",AM31="OK",AM32="OK",AM33="OK",AM34="OK",AM35="OK",AM36="OK"),"OK","niet OK") | AD40: t.a.v. ontwerpstroom
C41: Huidige aansluitwaarde: 3x35A t/m 3x40A | D41: > G25 | F41: 65 | G41: 65 | H41: =F41*B41 | I41: =G41*B41 | J41: =F41*0.23*3*B41 | K41: =G41*0.23*3*B41 | W41: =IF(AND(W38="OK",W40="OK"),"JA","NEE") | X41: =IF(AND(X38="OK",X40="OK"),"JA","NEE") | Y41: =IF(AND(Y38="OK",Y40="OK"),"JA","NEE") | Z41: =IF(AND(Z38="OK",Z40="OK"),"JA","NEE") | AA41: =IF(AND(AA38="OK",AA40="OK"),"JA","NEE") | AB41: =IF(AND(AB38="OK",AB40="OK"),"JA","NEE") | AC41: =IF(AND(AC38="OK",AC40="OK"),"JA","NEE") | AD41: voldoet aan beide / toegestaan met passieve transformator en gG zekeringen?
...

Sheet (2)
A1: Vul alleen de | C1: vlakken in. | F1: Ontwerpstroom kabel | O1: Verschillende doorsnedes in dezelfde kabelgroep! Let op: Alleen de gele velden zijn invoervelden ! | AD1: Invoervelden
B2: Aantal van eenheid | C2: Type wooneenheid | F2: Ontwerpstroom verbruik per eenheid | G2: Ontwerpstroom opwek per eenheid | H2: Totaal verbruik op kabelniveau in A | I2: Totaal opwek op kabelniveau in A | J2: Totaal verbruik op kabelniveau in kW | K2: Totaal opwek op kabelniveau in kW | M2: Opmerkingen | O2: Evenredig verdeelde belasting over de kabel (50%), gebaseerd op tabellen 6 en 8 uit kader Eea-0205.K
O3: Er moet wel sprake zijn van zogenaamde kabelverjonging, d.w.z. de zwaardere kabels aan het begin van de kabelgroep en de dunnere kabels op het eind van de kabelgroep.
C4: Type 1: Laagbouw huishoudens t/m bouwjaar 2021 met een individuele warmtepomp en tapwaterbuffer
C5: Vrijstaand | F5: 8.1 | G5: 9.2 | H5: =F5*B5 | I5: =G5*B5 | J5: =F5*0.23*3*B5 | K5: =G5*0.23*3*B5
C6: Twee onder een kap | F6: 7.1 | G6: 7 | H6: =F6*B6 | I6: =G6*B6 | J6: =F6*0.23*3*B6 | K6: =G6*0.23*3*B6
C7: Rijtjeswoning (woonboten, woonwagens, chalets en vakantiehuisjes) | F7: 6.4 | G7: 5.9 | H7: =F7*B7 | I7: =G7*B7 | J7: =F7*0.23*3*B7 | K7: =G7*0.23*3*B7
C8: Onbekend | F8: 6.8 | G8: 5.9 | H8: =F8*B8 | I8: =G8*B8 | J8: =F8*0.23*3*B8 | K8: =G8*0.23*3*B8
C10: Type 2: Laagbouw huishoudens met stads- of gasverwarming
C11: Vrijstaand | F11: 3.9 | G11: 8.9 | H11: =F11*B11 | I11: =G11*B11 | J11: =F11*0.23*3*B11 | K11: =G11*0.23*3*B11
C12: Twee onder een kap | F12: 3.9 | G12: 6.8 | H12: =F12*B12 | I12: =G12*B12 | J12: =F12*0.23*3*B12 | K12: =G12*0.23*3*B12 | O12: ontwerpstroom | W12: t/m 57A | X12: t/m 72A | Y12: t/m 90A | Z12: t/m 113A | AA12: t/m 144A | AB12: t/m 180A | AC12: t/m 225A
C13: Rijtjeswoning (woonboten, woonwagens, chalets en vakantiehuisjes) | F13: 3.9 | G13: 5.7 | H13: =F13*B13 | I13: =G13*B13 | J13: =F13*0.23*3*B13 | K13: =G13*0.23*3*B13 | O13: smeltveiligheid Inom | W13: 63A | X13: 80A | Y13: 100A | Z13: 125A | AA13: 160A | AB13: 200A | AC13: 250A | AD13: invoer
C14: Onbekend | F14: 3.9 | G14: 5.7 | H14: =F14*B14 | I14: =G14*B14 | J14: =F14*0.23*3*B14 | K14: =G14*0.23*3*B14 | P14: waarden per 1000m | S14: waarden o.b.v. kabellengte | W14: 63 | X14: 80 | Y14: 100 | Z14: 125 | AA14: 160 | AB14: 200 | AC14: 250 | AD14: kabellengtes
P15: ohm | Q15: ohm | R15: ohm | S15: ohm | T15: ohm | U15: ohm | V15: A | W15: ohm | X15: ohm | Y15: ohm | Z15: ohm | AA15: ohm | AB15: ohm | AC15: ohm | AD15: per doorsnede
C16: Type 3: Laagbouw huishoudens vanaf bouwjaar 2022 met een individuele warmtepomp en tapwaterbuffer | W16: 0.25 | X16: 0.25 | Y16: 0.204 | Z16: 0.163 | AA16: 0.128 | AB16: 0.092 | AC16: 0.062
C17: Vrijstaand | F17: 7.54 | G17: 9.2 | H17: =F17*B17 | I17: =G17*B17 | J17: =F17*0.23*3*B17 | K17: =G17*0.23*3*B17 | O17: Name | P17: R | Q17: X | R17: Z (berekend) | S17: R | T17: X | U17: Z (berekend) | W17: 0.25 | X17: 0.25 | Y17: 0.25 | Z17: 0.25 | AA17: 0.25 | AB17: 0.218 | AC17: 0.171 | AD17: in meters | AI17: hulptabel
C18: Twee onder een kap | F18: 6.8 | G18: 7 | H18: =F18*B18 | I18: =G18*B18 | J18: =F18*0.23*3*B18 | K18: =G18*0.23*3*B18 | O18: 4*240mm2 Al | P18: 0.129 | Q18: 0.073 | R18: =SQRT(P18^2+Q18^2) | S18: =+P18*AD18/1000 | T18: =+AD18*Q18/1000 | V18: 359 | W18: =IF(W14<=V18+3,+AD18,"X") | X18: =IF(X14<=V18+3,+AD18,"X") | Y18: =IF(Y14<=V18+3,+AD18,"X") | Z18: =IF(Z14<=V18+3,+AD18,"X") | AA18: =IF(AA14<=V18+3,+AD18,"X") | AB18: =IF(AB14<=V18+3,+AD18,"X") | AC18: =IF(AC14<=V18+3,+AD18,"X") | AE18: 4*240mm2 Al | AG18: =IF(OR(W18=AD18,AND(AD18=0,W18="X")),"OK","niet OK") | AH18: =IF(OR(X18=AD18,AND(AD18=0,X18="X")),"OK","niet OK") | AI18: =IF(OR(Y18=AD18,AND(AD18=0,Y18="X")),"OK","niet OK") | AJ18: =IF(OR(Z18=AD18,AND(AD18=0,Z18="X")),"OK","niet OK") | AK18: =IF(OR(AA18=AD18,AND(AD18=0,AA18="X")),"OK","niet OK") | AL18: =IF(OR(AB18=AD18,AND(AD18=0,AB18="X")),"OK","niet OK") | AM18: =IF(OR(AC18=AD18,AND(AD18=0,AC18="X")),"OK","niet OK")
C19: Rijtjeswoning | F19: 6.3 | G19: 5.9 | H19: =F19*B19 | I19: =G19*B19 | J19: =F19*0.23*3*B19 | K19: =G19*0.23*3*B19 | O19: 4*150mm2 Al | P19: 0.206 | Q19: 0.079 | R19: =SQRT(P19^2+Q19^2) | S19: =+P19*AD19/1000 | T19: =+AD19*Q19/1000 | V19: 272 | W19: =IF(W14<=V19+3,+AD19,"X") | X19: =IF(X14<=V19+3,+AD19,"X") | Y19: =IF(Y14<=V19+3,+AD19,"X") | Z19: =IF(Z14<=V19+3,+AD19,"X") | AA19: =IF(AA14<=V19+3,+AD19,"X") | AB19: =IF(AB14<=V19+3,+AD19,"X") | AC19: =IF(AC14<=V19+3,+AD19,"X") | AE19: 4*150mm2 Al | AG19: =IF(OR(W19=AD19,AND(AD19=0,W19="X")),"OK","niet OK") | AH19: =IF(OR(X19=AD19,AND(AD19=0,X19="X")),"OK","niet OK") | AI19: =IF(OR(Y19=AD19,AND(AD19=0,Y19="X")),"OK","niet OK") | AJ19: =IF(OR(Z19=AD19,AND(AD19=0,Z19="X")),"OK","niet OK") | AK19: =IF(OR(AA19=AD19,AND(AD19=0,AA19="X")),"OK","niet OK") | AL19: =IF(OR(AB19=AD19,AND(AD19=0,AB19="X")),"OK","niet OK") | AM19: =IF(OR(AC19=AD19,AND(AD19=0,AC19="X")),"OK","niet OK")
C20: Onbekend | F20: 6.4 | G20: 5.9 | H20: =F20*B20 | I20: =G20*B20 | J20: =F20*0.23*3*B20 | K20: =G20*0.23*3*B20 | O20: 4*120mm2 Al | P20: 0.281 | Q20: 0.081 | R20: =SQRT(P20^2+Q20^2) | S20: =+P20*AD20/1000 | T20: =+AD20*Q20/1000 | V20: 243 | W20: =IF(W14<=V20+3,+AD20,"X") | X20: =IF(X14<=V20+3,+AD20,"X") | Y20: =IF(Y14<=V20+3,+AD20,"X") | Z20: =IF(Z14<=V20+3,+AD20,"X") | AA20: =IF(AA14<=V20+3,+AD20,"X") | AB20: =IF(AB14<=V20+3,+AD20,"X") | AC20: =IF(AC14<=V20+3,+AD20,"X") | AE20: 4*120mm2 Al | AG20: =IF(OR(W20=AD20,AND(AD20=0,W20="X")),"OK","niet OK") | AH20: =IF(OR(X20=AD20,AND(AD20=0,X20="X")),"OK","niet OK") | AI20: =IF(OR(Y20=AD20,AND(AD20=0,Y20="X")),"OK","niet OK") | AJ20: =IF(OR(Z20=AD20,AND(AD20=0,Z20="X")),"OK","niet OK") | AK20: =IF(OR(AA20=AD20,AND(AD20=0,AA20="X")),"OK","niet OK") | AL20: =IF(OR(AB20=AD20,AND(AD20=0,AB20="X")),"OK","niet OK") | AM20: =IF(OR(AC20=AD20,AND(AD20=0,AC20="X")),"OK","niet OK")
O21: 4*95mm2 Al | P21: 0.32 | Q21: 0.082 | R21: =SQRT(P21^2+Q21^2) | S21: =+P21*AD21/1000 | T21: =+AD21*Q21/1000 | V21: 213 | W21: =IF(W14<=V21+3,+AD21,"X") | X21: =IF(X14<=V21+3,+AD21,"X") | Y21: =IF(Y14<=V21+3,+AD21,"X") | Z21: =IF(Z14<=V21+3,+AD21,"X") | AA21: =IF(AA14<=V21+3,+AD21,"X") | AB21: =IF(AB14<=V21+3,+AD21,"X") | AC21: =IF(AC14<=V21+3,+AD21,"X") | AE21: 4*95mm2 Al | AG21: =IF(OR(W21=AD21,AND(AD21=0,W21="X")),"OK","niet OK") | AH21: =IF(OR(X21=AD21,AND(AD21=0,X21="X")),"OK","niet OK") | AI21: =IF(OR(Y21=AD21,AND(AD21=0,Y21="X")),"OK","niet OK") | AJ21: =IF(OR(Z21=AD21,AND(AD21=0,Z21="X")),"OK","niet OK") | AK21: =IF(OR(AA21=AD21,AND(AD21=0,AA21="X")),"OK","niet OK") | AL21: =IF(OR(AB21=AD21,AND(AD21=0,AB21="X")),"OK","niet OK") | AM21: =IF(OR(AC21=AD21,AND(AD21=0,AC21="X")),"OK","niet OK")
C22: Type 4: Hoogbouw huishoudens met collectieve warmtepomp, stads- of gasverwarming | O22: 4*70mm2 Al | P22: 0.443 | Q22: =(Q21+Q23)/2 | R22: =SQRT(P22^2+Q22^2) | S22: =+P22*AD22/1000 | T22: =+AD22*Q22/1000 | V22: 177 | W22: =IF(W14<=V22+3,+AD22,"X") | X22: =IF(X14<=V22+3,+AD22,"X") | Y22: =IF(Y14<=V22+3,+AD22,"X") | Z22: =IF(Z14<=V22+3,+AD22,"X") | AA22: =IF(AA14<=V22+3,+AD22,"X") | AB22: =IF(AB14<=V22+3,+AD22,"X") | AC22: =IF(AC14<=V22+3,+AD22,"X") | AE22: 4*70mm2 Al | AG22: =IF(OR(W22=AD22,AND(AD22=0,W22="X")),"OK","niet OK") | AH22: =IF(OR(X22=AD22,AND(AD22=0,X22="X")),"OK","niet OK") | AI22: =IF(OR(Y22=AD22,AND(AD22=0,Y22="X")),"OK","niet OK") | AJ22: =IF(OR(Z22=AD22,AND(AD22=0,Z22="X")),"OK","niet OK") | AK22: =IF(OR(AA22=AD22,AND(AD22=0,AA22="X")),"OK","niet OK") | AL22: =IF(OR(AB22=AD22,AND(AD22=0,AB22="X")),"OK","niet OK") | AM22: =IF(OR(AC22=AD22,AND(AD22=0,AC22="X")),"OK","niet OK")
C23: Appartement incl. publiek laden | F23: 3.4 | H23: =F23*B23 | J23: =F23*0.23*3*B23 | O23: 4*50mm2 Al | P23: 0.641 | Q23: 0.085 | R23: =SQRT(P23^2+Q23^2) | S23: =+P23*AD23/1000 | T23: =+AD23*Q23/1000 | V23: 144 | W23: =IF(W14<=V23+3,+AD23,"X") | X23: =IF(X14<=V23+3,+AD23,"X") | Y23: =IF(Y14<=V23+3,+AD23,"X") | Z23: =IF(Z14<=V23+3,+AD23,"X") | AA23: =IF(AA14<=V23+3,+AD23,"X") | AB23: =IF(AB14<=V23+3,+AD23,"X") | AC23: =IF(AC14<=V23+3,+AD23,"X") | AE23: 4*50mm2 Al | AG23: =IF(OR(W23=AD23,AND(AD23=0,W23="X")),"OK","niet OK") | AH23: =IF(OR(X23=AD23,AND(AD23=0,X23="X")),"OK","niet OK") | AI23: =IF(OR(Y23=AD23,AND(AD23=0,Y23="X")),"OK","niet OK") | AJ23: =IF(OR(Z23=AD23,AND(AD23=0,Z23="X")),"OK","niet OK") | AK23: =IF(OR(AA23=AD23,AND(AD23=0,AA23="X")),"OK","niet OK") | AL23: =IF(OR(AB23=AD23,AND(AD23=0,AB23="X")),"OK","niet OK") | AM23: =IF(OR(AC23=AD23,AND(AD23=0,AC23="X")),"OK","niet OK")
C24: Collectieve warmtepomp - elektrisch vermogen | H24: =J24*1000/(3*230) | O24: 4*35mm2 Al | P24: 0.868 | Q24: 0.101 | R24: =SQRT(P24^2+Q24^2) | S24: =+P24*AD24/1000 | T24: =+AD24*Q24/1000 | V24: 120 | W24: =IF(W14<=V24+3,+AD24,"X") | X24: =IF(X14<=V24+3,+AD24,"X") | Y24: =IF(Y14<=V24+3,+AD24,"X") | Z24: =IF(Z14<=V24+3,+AD24,"X") | AA24: =IF(AA14<=V24+3,+AD24,"X") | AB24: =IF(AB14<=V24+3,+AD24,"X") | AC24: =IF(AC14<=V24+3,+AD24,"X") | AE24: 4*35mm2 Al | AG24: =IF(OR(W24=AD24,AND(AD24=0,W24="X")),"OK","niet OK") | AH24: =IF(OR(X24=AD24,AND(AD24=0,X24="X")),"OK","niet OK") | AI24: =IF(OR(Y24=AD24,AND(AD24=0,Y24="X")),"OK","niet OK") | AJ24: =IF(OR(Z24=AD24,AND(AD24=0,Z24="X")),"OK","niet OK") | AK24: =IF(OR(AA24=AD24,AND(AD24=0,AA24="X")),"OK","niet OK") | AL24: =IF(OR(AB24=AD24,AND(AD24=0,AB24="X")),"OK","niet OK") | AM24: =IF(OR(AC24=AD24,AND(AD24=0,AC24="X")),"OK","niet OK")
O25: 4*25mm2 Al | P25: 1.2 | Q25: 0.094 | R25: =SQRT(P25^2+Q25^2) | S25: =+P25*AD25/1000 | T25: =+AD25*Q25/1000 | V25: 100 | W25: =IF(W14<=V25+3,+AD25,"X") | X25: =IF(X14<=V25+3,+AD25,"X") | Y25: =IF(Y14<=V25+3,+AD25,"X") | Z25: =IF(Z14<=V25+3,+AD25,"X") | AA25: =IF(AA14<=V25+3,+AD25,"X") | AB25: =IF(AB14<=V25+3,+AD25,"X") | AC25: =IF(AC14<=V25+3,+AD25,"X") | AE25: 4*25mm2 Al | AG25: =IF(OR(W25=AD25,AND(AD25=0,W25="X")),"OK","niet OK") | AH25: =IF(OR(X25=AD25,AND(AD25=0,X25="X")),"OK","niet OK") | AI25: =IF(OR(Y25=AD25,AND(AD25=0,Y25="X")),"OK","niet OK") | AJ25: =IF(OR(Z25=AD25,AND(AD25=0,Z25="X")),"OK","niet OK") | AK25: =IF(OR(AA25=AD25,AND(AD25=0,AA25="X")),"OK","niet OK") | AL25: =IF(OR(AB25=AD25,AND(AD25=0,AB25="X")),"OK","niet OK") | AM25: =IF(OR(AC25=AD25,AND(AD25=0,AC25="X")),"OK","niet OK")
C26: Type 5: Hoogbouw huishoudens t/m bouwjaar 2021 met een individuele warmtepomp | O26: 4*16mm2 Al | P26: 1.91 | Q26: 0.096 | R26: =SQRT(P26^2+Q26^2) | S26: =+P26*AD26/1000 | T26: =+AD26*Q26/1000 | V26: 78 | W26: =IF(W14<=V26+3,+AD26,"X") | X26: =IF(X14<=V26+3,+AD26,"X") | Y26: =IF(Y14<=V26+3,+AD26,"X") | Z26: =IF(Z14<=V26+3,+AD26,"X") | AA26: =IF(AA14<=V26+3,+AD26,"X") | AB26: =IF(AB14<=V26+3,+AD26,"X") | AC26: =IF(AC14<=V26+3,+AD26,"X") | AE26: 4*16mm2 Al | AG26: =IF(OR(W26=AD26,AND(AD26=0,W26="X")),"OK","niet OK") | AH26: =IF(OR(X26=AD26,AND(AD26=0,X26="X")),"OK","niet OK") | AI26: =IF(OR(Y26=AD26,AND(AD26=0,Y26="X")),"OK","niet OK") | AJ26: =IF(OR(Z26=AD26,AND(AD26=0,Z26="X")),"OK","niet OK") | AK26: =IF(OR(AA26=AD26,AND(AD26=0,AA26="X")),"OK","niet OK") | AL26: =IF(OR(AB26=AD26,AND(AD26=0,AB26="X")),"OK","niet OK") | AM26: =IF(OR(AC26=AD26,AND(AD26=0,AC26="X")),"OK","niet OK")
C27: Appartement incl. publiek laden | F27: 5.4 | H27: =F27*B27 | J27: =F27*0.23*3*B27
O28: 4*185mm2 Cu | P28: 0.107 | Q28: 0.068 | R28: =SQRT(P28^2+Q28^2) | S28: =+P28*AD28/1000 | T28: =+AD28*Q28/1000 | V28: 393 | W28: =IF(W14<=V28+3,+AD28,"X") | X28: =IF(X14<=V28+3,+AD28,"X") | Y28: =IF(Y14<=V28+3,+AD28,"X") | Z28: =IF(Z14<=V28+3,+AD28,"X") | AA28: =IF(AA14<=V28+3,+AD28,"X") | AB28: =IF(AB14<=V28+3,+AD28,"X") | AC28: =IF(AC14<=V28+3,+AD28,"X") | AE28: 4*185mm2 Cu | AG28: =IF(OR(W28=AD28,AND(AD28=0,W28="X")),"OK","niet OK") | AH28: =IF(OR(X28=AD28,AND(AD28=0,X28="X")),"OK","niet OK") | AI28: =IF(OR(Y28=AD28,AND(AD28=0,Y28="X")),"OK","niet OK") | AJ28: =IF(OR(Z28=AD28,AND(AD28=0,Z28="X")),"OK","niet OK") | AK28: =IF(OR(AA28=AD28,AND(AD28=0,AA28="X")),"OK","niet OK") | AL28: =IF(OR(AB28=AD28,AND(AD28=0,AB28="X")),"OK","niet OK") | AM28: =IF(OR(AC28=AD28,AND(AD28=0,AC28="X")),"OK","niet OK")
C29: Type 6: Nieuwbouw hoogbouw huishoudens vanaf bouwjaar 2022 met een individuele warmtepomp | O29: 4*150mm2 Cu | P29: 0.125 | Q29: 0.068 | R29: =SQRT(P29^2+Q29^2) | S29: =+P29*AD29/1000 | T29: =+AD29*Q29/1000 | V29: 348 | W29: =IF(W14<=V29+3,+AD29,"X") | X29: =IF(X14<=V29+3,+AD29,"X") | Y29: =IF(Y14<=V29+3,+AD29,"X") | Z29: =IF(Z14<=V29+3,+AD29,"X") | AA29: =IF(AA14<=V29+3,+AD29,"X") | AB29: =IF(AB14<=V29+3,+AD29,"X") | AC29: =IF(AC14<=V29+3,+AD29,"X") | AE29: 4*150mm2 Cu | AG29: =IF(OR(W29=AD29,AND(AD29=0,W29="X")),"OK","niet OK") | AH29: =IF(OR(X29=AD29,AND(AD29=0,X29="X")),"OK","niet OK") | AI29: =IF(OR(Y29=AD29,AND(AD29=0,Y29="X")),"OK","niet OK") | AJ29: =IF(OR(Z29=AD29,AND(AD29=0,Z29="X")),"OK","niet OK") | AK29: =IF(OR(AA29=AD29,AND(AD29=0,AA29="X")),"OK","niet OK") | AL29: =IF(OR(AB29=AD29,AND(AD29=0,AB29="X")),"OK","niet OK") | AM29: =IF(OR(AC29=AD29,AND(AD29=0,AC29="X")),"OK","niet OK")
C30: Appartement incl. publiek laden | F30: 5.1 | H30: =F30*B30 | J30: =F30*0.23*3*B30 | O30: 4*120mm2 Cu | P30: 0.152 | Q30: 0.069 | R30: 0.16692813 | S30: =+P30*AD30/1000 | T30: =+AD30*Q30/1000 | V30: 307 | W30: =IF(W14<=V30+3,+AD30,"X") | X30: =IF(X14<=V30+3,+AD30,"X") | Y30: =IF(Y14<=V30+3,+AD30,"X") | Z30: =IF(Z14<=V30+3,+AD30,"X") | AA30: =IF(AA14<=V30+3,+AD30,"X") | AB30: =IF(AB14<=V30+3,+AD30,"X") | AC30: =IF(AC14<=V30+3,+AD30,"X") | AE30: 4*120mm2 Cu | AG30: =IF(OR(W30=AD30,AND(AD30=0,W30="X")),"OK","niet OK") | AH30: =IF(OR(X30=AD30,AND(AD30=0,X30="X")),"OK","niet OK") | AI30: =IF(OR(Y30=AD30,AND(AD30=0,Y30="X")),"OK","niet OK") | AJ30: =IF(OR(Z30=AD30,AND(AD30=0,Z30="X")),"OK","niet OK") | AK30: =IF(OR(AA30=AD30,AND(AD30=0,AA30="X")),"OK","niet OK") | AL30: =IF(OR(AB30=AD30,AND(AD30=0,AB30="X")),"OK","niet OK") | AM30: =IF(OR(AC30=AD30,AND(AD30=0,AC30="X")),"OK","niet OK")
O31: 4*95mm2 Cu | P31: 0.194 | Q31: 0.069 | R31: =SQRT(P31^2+Q31^2) | S31: =+P31*AD31/1000 | T31: =+AD31*Q31/1000 | V31: 272 | W31: =IF(W14<=V31+3,+AD31,"X") | X31: =IF(X14<=V31+3,+AD31,"X") | Y31: =IF(Y14<=V31+3,+AD31,"X") | Z31: =IF(Z14<=V31+3,+AD31,"X") | AA31: =IF(AA14<=V31+3,+AD31,"X") | AB31: =IF(AB14<=V31+3,+AD31,"X") | AC31: =IF(AC14<=V31+3,+AD31,"X") | AE31: 4*95mm2 Cu | AG31: =IF(OR(W31=AD31,AND(AD31=0,W31="X")),"OK","niet OK") | AH31: =IF(OR(X31=AD31,AND(AD31=0,X31="X")),"OK","niet OK") | AI31: =IF(OR(Y31=AD31,AND(AD31=0,Y31="X")),"OK","niet OK") | AJ31: =IF(OR(Z31=AD31,AND(AD31=0,Z31="X")),"OK","niet OK") | AK31: =IF(OR(AA31=AD31,AND(AD31=0,AA31="X")),"OK","niet OK") | AL31: =IF(OR(AB31=AD31,AND(AD31=0,AB31="X")),"OK","niet OK") | AM31: =IF(OR(AC31=AD31,AND(AD31=0,AC31="X")),"OK","niet OK")
C32: Type 7: Laag- of hoogbouw met alternatieve verwarmingscomponenten (toeslag) | O32: 4*70mm2 Cu | P32: 0.268 | Q32: 0.072 | R32: =SQRT(P32^2+Q32^2) | S32: =+P32*AD32/1000 | T32: =+AD32*Q32/1000 | V32: 227 | W32: =IF(W14<=V32+3,+AD32,"X") | X32: =IF(X14<=V32+3,+AD32,"X") | Y32: =IF(Y14<=V32+3,+AD32,"X") | Z32: =IF(Z14<=V32+3,+AD32,"X") | AA32: =IF(AA14<=V32+3,+AD32,"X") | AB32: =IF(AB14<=V32+3,+AD32,"X") | AC32: =IF(AC14<=V32+3,+AD32,"X") | AE32: 4*70mm2 Cu | AG32: =IF(OR(W32=AD32,AND(AD32=0,W32="X")),"OK","niet OK") | AH32: =IF(OR(X32=AD32,AND(AD32=0,X32="X")),"OK","niet OK") | AI32: =IF(OR(Y32=AD32,AND(AD32=0,Y32="X")),"OK","niet OK") | AJ32: =IF(OR(Z32=AD32,AND(AD32=0,Z32="X")),"OK","niet OK") | AK32: =IF(OR(AA32=AD32,AND(AD32=0,AA32="X")),"OK","niet OK") | AL32: =IF(OR(AB32=AD32,AND(AD32=0,AB32="X")),"OK","niet OK") | AM32: =IF(OR(AC32=AD32,AND(AD32=0,AC32="X")),"OK","niet OK")
C33: Aantal * elektrisch vermogen verwarmingscomponent * gelijktijdigheidsfactor tabel type 7 | H33: =J33*1000/(3*230) | O33: 4*50mm2 Cu | P33: 0.387 | Q33: 0.085 | R33: =SQRT(P33^2+Q33^2) | S33: =+P33*AD33/1000 | T33: =+AD33*Q33/1000 | V33: 182 | W33: =IF(W14<=V33+3,+AD33,"X") | X33: =IF(X14<=V33+3,+AD33,"X") | Y33: =IF(Y14<=V33+3,+AD33,"X") | Z33: =IF(Z14<=V33+3,+AD33,"X") | AA33: =IF(AA14<=V33+3,+AD33,"X") | AB33: =IF(AB14<=V33+3,+AD33,"X") | AC33: =IF(AC14<=V33+3,+AD33,"X") | AE33: 4*50mm2 Cu | AG33: =IF(OR(W33=AD33,AND(AD33=0,W33="X")),"OK","niet OK") | AH33: =IF(OR(X33=AD33,AND(AD33=0,X33="X")),"OK","niet OK") | AI33: =IF(OR(Y33=AD33,AND(AD33=0,Y33="X")),"OK","niet OK") | AJ33: =IF(OR(Z33=AD33,AND(AD33=0,Z33="X")),"OK","niet OK") | AK33: =IF(OR(AA33=AD33,AND(AD33=0,AA33="X")),"OK","niet OK") | AL33: =IF(OR(AB33=AD33,AND(AD33=0,AB33="X")),"OK","niet OK") | AM33: =IF(OR(AC33=AD33,AND(AD33=0,AC33="X")),"OK","niet OK")
O34: 4*35mm2 Cu | P34: 0.524 | Q34: 0.1 | R34: =SQRT(P34^2+Q34^2) | S34: =+P34*AD34/1000 | T34: =+AD34*Q34/1000 | V34: 154 | W34: =IF(W14<=V34+3,+AD34,"X") | X34: =IF(X14<=V34+3,+AD34,"X") | Y34: =IF(Y14<=V34+3,+AD34,"X") | Z34: =IF(Z14<=V34+3,+AD34,"X") | AA34: =IF(AA14<=V34+3,+AD34,"X") | AB34: =IF(AB14<=V34+3,+AD34,"X") | AC34: =IF(AC14<=V34+3,+AD34,"X") | AE34: 4*35mm2 Cu | AG34: =IF(OR(W34=AD34,AND(AD34=0,W34="X")),"OK","niet OK") | AH34: =IF(OR(X34=AD34,AND(AD34=0,X34="X")),"OK","niet OK") | AI34: =IF(OR(Y34=AD34,AND(AD34=0,Y34="X")),"OK","niet OK") | AJ34: =IF(OR(Z34=AD34,AND(AD34=0,Z34="X")),"OK","niet OK") | AK34: =IF(OR(AA34=AD34,AND(AD34=0,AA34="X")),"OK","niet OK") | AL34: =IF(OR(AB34=AD34,AND(AD34=0,AB34="X")),"OK","niet OK") | AM34: =IF(OR(AC34=AD34,AND(AD34=0,AC34="X")),"OK","niet OK")
C35: Type 8: Kleinzakelijk (niet-huishoudelijk t/m 3x80A) | O35: 4*25mm2 Cu | P35: 0.727 | Q35: 0.094 | R35: =SQRT(P35^2+Q35^2) | S35: =+P35*AD35/1000 | T35: =+AD35*Q35/1000 | V35: 128 | W35: =IF(W14<=V35+3,+AD35,"X") | X35: =IF(X14<=V35+3,+AD35,"X") | Y35: =IF(Y14<=V35+3,+AD35,"X") | Z35: =IF(Z14<=V35+3,+AD35,"X") | AA35: =IF(AA14<=V35+3,+AD35,"X") | AB35: =IF(AB14<=V35+3,+AD35,"X") | AC35: =IF(AC14<=V35+3,+AD35,"X") | AE35: 4*25mm2 Cu | AG35: =IF(OR(W35=AD35,AND(AD35=0,W35="X")),"OK","niet OK") | AH35: =IF(OR(X35=AD35,AND(AD35=0,X35="X")),"OK","niet OK") | AI35: =IF(OR(Y35=AD35,AND(AD35=0,Y35="X")),"OK","niet OK") | AJ35: =IF(OR(Z35=AD35,AND(AD35=0,Z35="X")),"OK","niet OK") | AK35: =IF(OR(AA35=AD35,AND(AD35=0,AA35="X")),"OK","niet OK") | AL35: =IF(OR(AB35=AD35,AND(AD35=0,AB35="X")),"OK","niet OK") | AM35: =IF(OR(AC35=AD35,AND(AD35=0,AC35="X")),"OK","niet OK")
C36: Huidige aansluitwaarde: < 3x35A | D36: G4, G6, geen of ander gas | F36: 8.7 | G36: 8.7 | H36: =F36*B36 | I36: =G36*B36 | J36: =F36*0.23*3*B36 | K36: =G36*0.23*3*B36 | O36: 4*16mm2 Cu | P36: 1.15 | Q36: 0.097 | R36: =SQRT(P36^2+Q36^2) | S36: =+P36*AD36/1000 | T36: =+AD36*Q36/1000 | V36: 99 | W36: =IF(W14<=V36+3,+AD36,"X") | X36: =IF(X14<=V36+3,+AD36,"X") | Y36: =IF(Y14<=V36+3,+AD36,"X") | Z36: =IF(Z14<=V36+3,+AD36,"X") | AA36: =IF(AA14<=V36+3,+AD36,"X") | AB36: =IF(AB14<=V36+3,+AD36,"X") | AC36: =IF(AC14<=V36+3,+AD36,"X") | AE36: 4*16mm2 Cu | AG36: =IF(OR(W36=AD36,AND(AD36=0,W36="X")),"OK","niet OK") | AH36: =IF(OR(X36=AD36,AND(AD36=0,X36="X")),"OK","niet OK") | AI36: =IF(OR(Y36=AD36,AND(AD36=0,Y36="X")),"OK","niet OK") | AJ36: =IF(OR(Z36=AD36,AND(AD36=0,Z36="X")),"OK","niet OK") | AK36: =IF(OR(AA36=AD36,AND(AD36=0,AA36="X")),"OK","niet OK") | AL36: =IF(OR(AB36=AD36,AND(AD36=0,AB36="X")),"OK","niet OK") | AM36: =IF(OR(AC36=AD36,AND(AD36=0,AC36="X")),"OK","niet OK")
C37: Huidige aansluitwaarde: < 3x35A | D37: G10 t/m G25 | F37: 44 | G37: 44 | H37: =F37*B37 | I37: =G37*B37 | J37: =F37*0.23*3*B37 | K37: =G37*0.23*3*B37
C38: Huidige aansluitwaarde: < 3x35A | D38: > G25 | F38: 65 | G38: 65 | H38: =F38*B38 | I38: =G38*B38 | J38: =F38*0.23*3*B38 | K38: =G38*0.23*3*B38 | O38: totale samengestelde impedantie | S38: =SUM(S18:S37) | T38: =SUM(T18:T37) | U38: =SQRT(S38^2+T38^2) | W38: =IF(U38<=W16,"OK","niet OK") | X38: =IF(U38<=X16,"OK","niet OK") | Y38: =IF(U38<=Y16,"OK","niet OK") | Z38: =IF(U38<=Z16,"OK","niet OK") | AA38: =IF(U38<=AA16,"OK","niet OK") | AB38: =IF(U38<=AB16,"OK","niet OK") | AC38: =IF(U38<=AC16,"OK","niet OK") | AD38: t.a.v. totale impedantie passieve trafo en gG
C39: Huidige aansluitwaarde: 3x35A t/m 3x40A | D39: G4, G6, geen of ander gas | F39: 32 | G39: 32 | H39: =F39*B39 | I39: =G39*B39 | J39: =F39*0.23*3*B39 | K39: =G39*0.23*3*B39 | W39: =IF(U38<=W17,"OK","niet OK") | X39: =IF(U38<=X17,"OK","niet OK") | Y39: =IF(U38<=Y17,"OK","niet OK") | Z39: =IF(U38<=Z17,"OK","niet OK") | AA39: =IF(U38<=AA17,"OK","niet OK") | AB39: =IF(U38<=AB17,"OK","niet OK") | AC39: =IF(U38<=AC17,"OK","niet OK") | AD39: t.a.v. totale impedantie regeltrafo en gFF
C40: Huidige aansluitwaarde: 3x35A t/m 3x40A | D40: G10 t/m G25 | F40: 65 | G40: 65 | H40: =F40*B40 | I40: =G40*B40 | J40: =F40*0.23*3*B40 | K40: =G40*0.23*3*B40 | W40: =IF(AND(AG18="OK",AG19="OK",AG20="OK",AG21="OK",AG22="OK",AG23="OK",AG24="OK",AG25="OK",AG26="OK",AG28="OK",AG29="OK",AG31="OK",AG32="OK",AG33="OK",AG34="OK",AG35="OK",AG36="OK"),"OK","niet OK") | X40: =IF(AND(AH18="OK",AH19="OK",AH20="OK",AH21="OK",AH22="OK",AH23="OK",AH24="OK",AH25="OK",AH26="OK",AH28="OK",AH29="OK",AH31="OK",AH32="OK",AH33="OK",AH34="OK",AH35="OK",AH36="OK"),"OK","niet OK") | Y40: =IF(AND(AI18="OK",AI19="OK",AI20="OK",AI21="OK",AI22="OK",AI23="OK",AI24="OK",AI25="OK",AI26="OK",AI28="OK",AI29="OK",AI31="OK",AI32="OK",AI33="OK",AI34="OK",AI35="OK",AI36="OK"),"OK","niet OK") | Z40: =IF(AND(AJ18="OK",AJ19="OK",AJ20="OK",AJ21="OK",AJ22="OK",AJ23="OK",AJ24="OK",AJ25="OK",AJ26="OK",AJ28="OK",AJ29="OK",AJ31="OK",AJ32="OK",AJ33="OK",AJ34="OK",AJ35="OK",AJ36="OK"),"OK","niet OK") | AA40: =IF(AND(AK18="OK",AK19="OK",AK20="OK",AK21="OK",AK22="OK",AK23="OK",AK24="OK",AK25="OK",AK26="OK",AK28="OK",AK29="OK",AK31="OK",AK32="OK",AK33="OK",AK34="OK",AK35="OK",AK36="OK"),"OK","niet OK") | AB40: =IF(AND(AL18="OK",AL19="OK",AL20="OK",AL21="OK",AL22="OK",AL23="OK",AL24="OK",AL25="OK",AL26="OK",AL28="OK",AL29="OK",AL31="OK",AL32="OK",AL33="OK",AL34="OK",AL35="OK",AL36="OK"),"OK","niet OK") | AC40: =IF(AND(AM18="OK",AM19="OK",AM20="OK",AM21="OK",AM22="OK",AM23="OK",AM24="OK",AM25="OK",AM26="OK",AM28="OK",AM29="OK",AM31="OK",AM32="OK",AM33="OK",AM34="OK",AM35="OK",AM36="OK"),"OK","niet OK") | AD40: t.a.v. ontwerpstroom
C41: Huidige aansluitwaarde: 3x35A t/m 3x40A | D41: > G25 | F41: 65 | G41: 65 | H41: =F41*B41 | I41: =G41*B41 | J41: =F41*0.23*3*B41 | K41: =G41*0.23*3*B41 | W41: =IF(AND(W38="OK",W40="OK"),"JA","NEE") | X41: =IF(AND(X38="OK",X40="OK"),"JA","NEE") | Y41: =IF(AND(Y38="OK",Y40="OK"),"JA","NEE") | Z41: =IF(AND(Z38="OK",Z40="OK"),"JA","NEE") | AA41: =IF(AND(AA38="OK",AA40="OK"),"JA","NEE") | AB41: =IF(AND(AB38="OK",AB40="OK"),"JA","NEE") | AC41: =IF(AND(AC38="OK",AC40="OK"),"JA","NEE") | AD41: voldoet aan beide / toegestaan met passieve transformator en gG zekeringen?
...

Sheet (3)
A1: Vul alleen de | C1: vlakken in. | F1: Ontwerpstroom kabel | O1: Verschillende doorsnedes in dezelfde kabelgroep! Let op: Alleen de gele velden zijn invoervelden ! | AD1: Invoervelden
B2: Aantal van eenheid | C2: Type wooneenheid | F2: Ontwerpstroom verbruik per eenheid | G2: Ontwerpstroom opwek per eenheid | H2: Totaal verbruik op kabelniveau in A | I2: Totaal opwek op kabelniveau in A | J2: Totaal verbruik op kabelniveau in kW | K2: Totaal opwek op kabelniveau in kW | M2: Opmerkingen | O2: Evenredig verdeelde belasting over de kabel (50%), gebaseerd op tabellen 6 en 8 uit kader Eea-0205.K
O3: Er moet wel sprake zijn van zogenaamde kabelverjonging, d.w.z. de zwaardere kabels aan het begin van de kabelgroep en de dunnere kabels op het eind van de kabelgroep.
C4: Type 1: Laagbouw huishoudens t/m bouwjaar 2021 met een individuele warmtepomp en tapwaterbuffer
C5: Vrijstaand | F5: 8.1 | G5: 9.2 | H5: =F5*B5 | I5: =G5*B5 | J5: =F5*0.23*3*B5 | K5: =G5*0.23*3*B5
C6: Twee onder een kap | F6: 7.1 | G6: 7 | H6: =F6*B6 | I6: =G6*B6 | J6: =F6*0.23*3*B6 | K6: =G6*0.23*3*B6
C7: Rijtjeswoning (woonboten, woonwagens, chalets en vakantiehuisjes) | F7: 6.4 | G7: 5.9 | H7: =F7*B7 | I7: =G7*B7 | J7: =F7*0.23*3*B7 | K7: =G7*0.23*3*B7
C8: Onbekend | F8: 6.8 | G8: 5.9 | H8: =F8*B8 | I8: =G8*B8 | J8: =F8*0.23*3*B8 | K8: =G8*0.23*3*B8
C10: Type 2: Laagbouw huishoudens met stads- of gasverwarming
C11: Vrijstaand | F11: 3.9 | G11: 8.9 | H11: =F11*B11 | I11: =G11*B11 | J11: =F11*0.23*3*B11 | K11: =G11*0.23*3*B11
C12: Twee onder een kap | F12: 3.9 | G12: 6.8 | H12: =F12*B12 | I12: =G12*B12 | J12: =F12*0.23*3*B12 | K12: =G12*0.23*3*B12 | O12: ontwerpstroom | W12: t/m 57A | X12: t/m 72A | Y12: t/m 90A | Z12: t/m 113A | AA12: t/m 144A | AB12: t/m 180A | AC12: t/m 225A
C13: Rijtjeswoning (woonboten, woonwagens, chalets en vakantiehuisjes) | F13: 3.9 | G13: 5.7 | H13: =F13*B13 | I13: =G13*B13 | J13: =F13*0.23*3*B13 | K13: =G13*0.23*3*B13 | O13: smeltveiligheid Inom | W13: 63A | X13: 80A | Y13: 100A | Z13: 125A | AA13: 160A | AB13: 200A | AC13: 250A | AD13: invoer
C14: Onbekend | F14: 3.9 | G14: 5.7 | H14: =F14*B14 | I14: =G14*B14 | J14: =F14*0.23*3*B14 | K14: =G14*0.23*3*B14 | P14: waarden per 1000m | S14: waarden o.b.v. kabellengte | W14: 63 | X14: 80 | Y14: 100 | Z14: 125 | AA14: 160 | AB14: 200 | AC14: 250 | AD14: kabellengtes
P15: ohm | Q15: ohm | R15: ohm | S15: ohm | T15: ohm | U15: ohm | V15: A | W15: ohm | X15: ohm | Y15: ohm | Z15: ohm | AA15: ohm | AB15: ohm | AC15: ohm | AD15: per doorsnede
C16: Type 3: Laagbouw huishoudens vanaf bouwjaar 2022 met een individuele warmtepomp en tapwaterbuffer | W16: 0.25 | X16: 0.25 | Y16: 0.204 | Z16: 0.163 | AA16: 0.128 | AB16: 0.092 | AC16: 0.062
C17: Vrijstaand | F17: 7.54 | G17: 9.2 | H17: =F17*B17 | I17: =G17*B17 | J17: =F17*0.23*3*B17 | K17: =G17*0.23*3*B17 | O17: Name | P17: R | Q17: X | R17: Z (berekend) | S17: R | T17: X | U17: Z (berekend) | W17: 0.25 | X17: 0.25 | Y17: 0.25 | Z17: 0.25 | AA17: 0.25 | AB17: 0.218 | AC17: 0.171 | AD17: in meters | AI17: hulptabel
C18: Twee onder een kap | F18: 6.8 | G18: 7 | H18: =F18*B18 | I18: =G18*B18 | J18: =F18*0.23*3*B18 | K18: =G18*0.23*3*B18 | O18: 4*240mm2 Al | P18: 0.129 | Q18: 0.073 | R18: =SQRT(P18^2+Q18^2) | S18: =+P18*AD18/1000 | T18: =+AD18*Q18/1000 | V18: 359 | W18: =IF(W14<=V18+3,+AD18,"X") | X18: =IF(X14<=V18+3,+AD18,"X") | Y18: =IF(Y14<=V18+3,+AD18,"X") | Z18: =IF(Z14<=V18+3,+AD18,"X") | AA18: =IF(AA14<=V18+3,+AD18,"X") | AB18: =IF(AB14<=V18+3,+AD18,"X") | AC18: =IF(AC14<=V18+3,+AD18,"X") | AE18: 4*240mm2 Al | AG18: =IF(OR(W18=AD18,AND(AD18=0,W18="X")),"OK","niet OK") | AH18: =IF(OR(X18=AD18,AND(AD18=0,X18="X")),"OK","niet OK") | AI18: =IF(OR(Y18=AD18,AND(AD18=0,Y18="X")),"OK","niet OK") | AJ18: =IF(OR(Z18=AD18,AND(AD18=0,Z18="X")),"OK","niet OK") | AK18: =IF(OR(AA18=AD18,AND(AD18=0,AA18="X")),"OK","niet OK") | AL18: =IF(OR(AB18=AD18,AND(AD18=0,AB18="X")),"OK","niet OK") | AM18: =IF(OR(AC18=AD18,AND(AD18=0,AC18="X")),"OK","niet OK")
